Traceback (most recent call last):
  File "C:\Users\sanga\AppData\Local\Programs\Python\Python311\Lib\site-packages\pyautogui\__init__.py", line 172, in wrapper
    return wrappedFunction(*args, **kwargs)
           ^^^^^^^^^^^^^^^^^^^^^^^^^^^^^^^^
  File "C:\Users\sanga\AppData\Local\Programs\Python\Python311\Lib\site-packages\pyautogui\__init__.py", line 210, in locateOnScreen
    return pyscreeze.locateOnScreen(*args, **kwargs)
           ^^^^^^^^^^^^^^^^^^^^^^^^^^^^^^^^^^^^^^^^^
  File "C:\Users\sanga\AppData\Local\Programs\Python\Python311\Lib\site-packages\pyscreeze\__init__.py", line 405, in locateOnScreen
    retVal = locate(image, screenshotIm, **kwargs)
             ^^^^^^^^^^^^^^^^^^^^^^^^^^^^^^^^^^^^^
checando vida...
  File "C:\Users\sanga\AppData\Local\Programs\Python\Python311\Lib\site-packages\pyscreeze\__init__.py", line 383, in locate
    points = tuple(locateAll(needleImage, haystackImage, **kwargs))
             ^^^^^^^^^^^^^^^^^^^^^^^^^^^^^^^^^^^^^^^^^^^^^^^^^^^^^^
  File "C:\Users\sanga\AppData\Local\Programs\Python\Python311\Lib\site-packages\pyscreeze\__init__.py", line 257, in _locateAll_opencv
    raise ImageNotFoundException('Could not locate the image (highest confidence = %.3f)' % result.max())
pyscreeze.ImageNotFoundException: Could not locate the image (highest confidence = 0.317)

During handling of the above exception, another exception occurred:

Traceback (most recent call last):
  File "C:\Users\sanga\AppData\Local\Programs\Python\Python311\Lib\threading.py", line 1045, in _bootstrap_inner
    self.run()
  File "C:\Users\sanga\AppData\Local\Programs\Python\Python311\Lib\threading.py", line 982, in run
    self._target(*self._args, **self._kwargs)
  File "c:\Users\sanga\OneDrive\Documents\abwasp35\main.py", line 151, in run        
    if not actions.check_anchor():
           ^^^^^^^^^^^^^^^^^^^^^^
  File "c:\Users\sanga\OneDrive\Documents\abwasp35\actions.py", line 38, in check_anchor
    box = pg.locateOnScreen("imgs/Anchfloor1.png", confidence=0.8)
          ^^^^^^^^^^^^^^^^^^^^^^^^^^^^^^^^^^^^^^^^^^^^^^^^^^^^^^^^
  File "C:\Users\sanga\AppData\Local\Programs\Python\Python311\Lib\site-packages\pyautogui\__init__.py", line 174, in wrapper
    raise ImageNotFoundException  # Raise PyAutoGUI's ImageNotFoundException.
    ^^^^^^^^^^^^^^^^^^^^^^^^^^^^
pyautogui.ImageNotFoundException
